Workbook

Sheet Painel Executivo Macro
A1: ="STATUS FUSÃO | PAINEL EXECUTIVO – ATIVIDADES - Frentes acompanhadas:"&COUNTA('Resumo por Frente'!$A$5:$A$17) -> STATUS FUSÃO | PAINEL EXECUTIVO – ATIVIDADES - Frentes acompanhadas:13
A3: Leitura do andamento das atividades Macro | Canceladas incluídas no total e fora do cálculo percentual
A5: Andamento das atividades Macro | K5: ="Total: "&COUNTIF('Atividades Micro'!$G$2:$G$554,"Macro") -> Total: 97
A6: Não iniciado | C6: Em andamento | E6: Testes QA | G6: Bloqueado | I6: Cancelado | K6: Finalizado
A7: =COUNTIFS('Atividades Micro'!$G$2:$G$554,"Macro",'Atividades Micro'!$J$2:$J$554,"Não iniciado") -> 25 | C7: =COUNTIFS('Atividades Micro'!$G$2:$G$554,"Macro",'Atividades Micro'!$J$2:$J$554,"Em andamento")-COUNTIFS('Atividades Micro'!$G$2:$G$554,"Micro",'Atividades Micro'!$E$2:$E$554,"*QA*",'Atividades Micro'!$J$2:$J$554,"Em andamento") -> 18 | E7: =COUNTIFS('Atividades Micro'!$G$2:$G$554,"Micro",'Atividades Micro'!$E$2:$E$554,"*QA*",'Atividades Micro'!$J$2:$J$554,"Em andamento") -> 1 | G7: =COUNTIFS('Atividades Micro'!$G$2:$G$554,"Macro",'Atividades Micro'!$J$2:$J$554,"Bloqueado") -> 12 | I7: =COUNTIFS('Atividades Micro'!$G$2:$G$554,"Macro",'Atividades Micro'!$J$2:$J$554,"Cancelado") -> 11 | K7: =COUNTIFS('Atividades Micro'!$G$2:$G$554,"Macro",'Atividades Micro'!$J$2:$J$554,"Finalizado") -> 30
A8: =IF(COUNTIFS('Atividades Micro'!$G$2:$G$554,"Macro",'Atividades Micro'!$J$2:$J$554,"<>Cancelado")<=0,0,COUNTIFS('Atividades Micro'!$G$2:$G$554,"Macro",'Atividades Micro'!$J$2:$J$554,"Não iniciado")/COUNTIFS('Atividades Micro'!$G$2:$G$554,"Macro",'Atividades Micro'!$J$2:$J$554,"<>Cancelado")) -> 0.29069767 | C8: =IF(COUNTIFS('Atividades Micro'!$G$2:$G$554,"Macro",'Atividades Micro'!$J$2:$J$554,"<>Cancelado")<=0,0,C7/COUNTIFS('Atividades Micro'!$G$2:$G$554,"Macro",'Atividades Micro'!$J$2:$J$554,"<>Cancelado")) -> 0.20930233 | E8: =IF(COUNTIFS('Atividades Micro'!$G$2:$G$554,"Macro",'Atividades Micro'!$J$2:$J$554,"<>Cancelado")<=0,0,E7/COUNTIFS('Atividades Micro'!$G$2:$G$554,"Macro",'Atividades Micro'!$J$2:$J$554,"<>Cancelado")) -> 0.011627907 | G8: =IF(COUNTIFS('Atividades Micro'!$G$2:$G$554,"Macro",'Atividades Micro'!$J$2:$J$554,"<>Cancelado")<=0,0,COUNTIFS('Atividades Micro'!$G$2:$G$554,"Macro",'Atividades Micro'!$J$2:$J$554,"Bloqueado")/COUNTIFS('Atividades Micro'!$G$2:$G$554,"Macro",'Atividades Micro'!$J$2:$J$554,"<>Cancelado")) -> 0.13953488 | I8: Fora do cálculo | K8: =IF(COUNTIFS('Atividades Micro'!$G$2:$G$554,"Macro",'Atividades Micro'!$J$2:$J$554,"<>Cancelado")<=0,0,COUNTIFS('Atividades Micro'!$G$2:$G$554,"Macro",'Atividades Micro'!$J$2:$J$554,"Finalizado")/COUNTIFS('Atividades Micro'!$G$2:$G$554,"Macro",'Atividades Micro'!$J$2:$J$554,"<>Cancelado")) -> 0.34883721
A11: Evolução das atividades Macro
A12: Atividade macro | B12: Frente | C12: Data Planejada | D12: Atividades macro | E12: Não iniciado | F12: Em andamento | G12: Testes QA | H12: Bloqueado | I12: Cancelado | J12: Finalizado | K12: % concluído
A13: ='Atividades Macro'!$B2 -> Infraestrutura - Fusão - Grupo PetzCobasi | B13: ='Atividades Macro'!$C2 -> (Migração ERP) Infraestrutura | C13: =IF('Atividades Macro'!$D2="","",'Atividades Macro'!$D2) -> 46374 | D13: ='Atividades Macro'!$F2 -> 12 | E13: =COUNTIFS('Atividades Micro'!$A$2:$A$554,$B13,'Atividades Micro'!$G$2:$G$554,"Macro",'Atividades Micro'!$J$2:$J$554,E$12) -> 7 | F13: =COUNTIFS('Atividades Micro'!$A$2:$A$554,$B13,'Atividades Micro'!$G$2:$G$554,"Macro",'Atividades Micro'!$J$2:$J$554,"Em andamento")-COUNTIFS('Atividades Micro'!$A$2:$A$554,$B13,'Atividades Micro'!$G$2:$G$554,"Micro",'Atividades Micro'!$E$2:$E$554,"*QA*",'Atividades Micro'!$J$2:$J$554,"Em andamento") -> 0 | G13: =COUNTIFS('Atividades Micro'!$A$2:$A$554,$B13,'Atividades Micro'!$G$2:$G$554,"Micro",'Atividades Micro'!$E$2:$E$554,"*QA*",'Atividades Micro'!$J$2:$J$554,"Em andamento") -> 0 | H13: =COUNTIFS('Atividades Micro'!$A$2:$A$554,$B13,'Atividades Micro'!$G$2:$G$554,"Macro",'Atividades Micro'!$J$2:$J$554,H$12) -> 0 | I13: =COUNTIFS('Atividades Micro'!$A$2:$A$554,$B13,'Atividades Micro'!$G$2:$G$554,"Macro",'Atividades Micro'!$J$2:$J$554,I$12) -> 0 | J13: =COUNTIFS('Atividades Micro'!$A$2:$A$554,$B13,'Atividades Micro'!$G$2:$G$554,"Macro",'Atividades Micro'!$J$2:$J$554,J$12) -> 5 | K13: 0.41666667
A14: ='Atividades Macro'!$B3 -> Migração de Dados/Saldo Inicial | Fusão Petz Cobasi | B14: ='Atividades Macro'!$C3 -> (Migração ERP) Dados Mestres | C14: =IF('Atividades Macro'!$D3="","",'Atividades Macro'!$D3) -> 46346 | D14: ='Atividades Macro'!$F3 -> 14 | E14: =COUNTIFS('Atividades Micro'!$A$2:$A$554,$B14,'Atividades Micro'!$G$2:$G$554,"Macro",'Atividades Micro'!$J$2:$J$554,E$12) -> 10 | F14: =COUNTIFS('Atividades Micro'!$A$2:$A$554,$B14,'Atividades Micro'!$G$2:$G$554,"Macro",'Atividades Micro'!$J$2:$J$554,"Em andamento")-COUNTIFS('Atividades Micro'!$A$2:$A$554,$B14,'Atividades Micro'!$G$2:$G$554,"Micro",'Atividades Micro'!$E$2:$E$554,"*QA*",'Atividades Micro'!$J$2:$J$554,"Em andamento") -> 0 | G14: =COUNTIFS('Atividades Micro'!$A$2:$A$554,$B14,'Atividades Micro'!$G$2:$G$554,"Micro",'Atividades Micro'!$E$2:$E$554,"*QA*",'Atividades Micro'!$J$2:$J$554,"Em andamento") -> 0 | H14: =COUNTIFS('Atividades Micro'!$A$2:$A$554,$B14,'Atividades Micro'!$G$2:$G$554,"Macro",'Atividades Micro'!$J$2:$J$554,H$12) -> 0 | I14: =COUNTIFS('Atividades Micro'!$A$2:$A$554,$B14,'Atividades Micro'!$G$2:$G$554,"Macro",'Atividades Micro'!$J$2:$J$554,I$12) -> 0 | J14: =COUNTIFS('Atividades Micro'!$A$2:$A$554,$B14,'Atividades Micro'!$G$2:$G$554,"Macro",'Atividades Micro'!$J$2:$J$554,J$12) -> 4 | K14: 0.25
A15: ='Atividades Macro'!$B4 -> Revisão de código e configurações | B15: ='Atividades Macro'!$C4 -> (Migração ERP) Refatoração / Fontes | C15: =IF('Atividades Macro'!$D4="","",'Atividades Macro'!$D4) -> 46272 | D15: ='Atividades Macro'!$F4 -> 9 | E15: =COUNTIFS('Atividades Micro'!$A$2:$A$554,$B15,'Atividades Micro'!$G$2:$G$554,"Macro",'Atividades Micro'!$J$2:$J$554,E$12) -> 1 | F15: =COUNTIFS('Atividades Micro'!$A$2:$A$554,$B15,'Atividades Micro'!$G$2:$G$554,"Macro",'Atividades Micro'!$J$2:$J$554,"Em andamento")-COUNTIFS('Atividades Micro'!$A$2:$A$554,$B15,'Atividades Micro'!$G$2:$G$554,"Micro",'Atividades Micro'!$E$2:$E$554,"*QA*",'Atividades Micro'!$J$2:$J$554,"Em andamento") -> 4 | G15: =COUNTIFS('Atividades Micro'!$A$2:$A$554,$B15,'Atividades Micro'!$G$2:$G$554,"Micro",'Atividades Micro'!$E$2:$E$554,"*QA*",'Atividades Micro'!$J$2:$J$554,"Em andamento") -> 0 | H15: =COUNTIFS('Atividades Micro'!$A$2:$A$554,$B15,'Atividades Micro'!$G$2:$G$554,"Macro",'Atividades Micro'!$J$2:$J$554,H$12) -> 0 | I15: =COUNTIFS('Atividades Micro'!$A$2:$A$554,$B15,'Atividades Micro'!$G$2:$G$554,"Macro",'Atividades Micro'!$J$2:$J$554,I$12) -> 1 | J15: =COUNTIFS('Atividades Micro'!$A$2:$A$554,$B15,'Atividades Micro'!$G$2:$G$554,"Macro",'Atividades Micro'!$J$2:$J$554,J$12) -> 3 | K15: 0.22222222
A16: ='Atividades Macro'!$B5 -> Sistemas Satelites | Fusão Petz Cobasi | B16: ='Atividades Macro'!$C5 -> (Migração ERP) Satélites | C16: =IF('Atividades Macro'!$D5="","",'Atividades Macro'!$D5) -> 46248 | D16: ='Atividades Macro'!$F5 -> 2 | E16: =COUNTIFS('Atividades Micro'!$A$2:$A$554,$B16,'Atividades Micro'!$G$2:$G$554,"Macro",'Atividades Micro'!$J$2:$J$554,E$12) -> 0 | F16: =COUNTIFS('Atividades Micro'!$A$2:$A$554,$B16,'Atividades Micro'!$G$2:$G$554,"Macro",'Atividades Micro'!$J$2:$J$554,"Em andamento")-COUNTIFS('Atividades Micro'!$A$2:$A$554,$B16,'Atividades Micro'!$G$2:$G$554,"Micro",'Atividades Micro'!$E$2:$E$554,"*QA*",'Atividades Micro'!$J$2:$J$554,"Em andamento") -> 1 | G16: =COUNTIFS('Atividades Micro'!$A$2:$A$554,$B16,'Atividades Micro'!$G$2:$G$554,"Micro",'Atividades Micro'!$E$2:$E$554,"*QA*",'Atividades Micro'!$J$2:$J$554,"Em andamento") -> 0 | H16: =COUNTIFS('Atividades Micro'!$A$2:$A$554,$B16,'Atividades Micro'!$G$2:$G$554,"Macro",'Atividades Micro'!$J$2:$J$554,H$12) -> 0 | I16: =COUNTIFS('Atividades Micro'!$A$2:$A$554,$B16,'Atividades Micro'!$G$2:$G$554,"Macro",'Atividades Micro'!$J$2:$J$554,I$12) -> 0 | J16: =COUNTIFS('Atividades Micro'!$A$2:$A$554,$B16,'Atividades Micro'!$G$2:$G$554,"Macro",'Atividades Micro'!$J$2:$J$554,J$12) -> 1 | K16: 0.5
A17: ='Atividades Macro'!$B6 -> FINANCEIRO | Fusão - Grupo Petz Cobasi | B17: ='Atividades Macro'!$C6 -> Financeiro | C17: =IF('Atividades Macro'!$D6="","",'Atividades Macro'!$D6) -> 46359 | D17: ='Atividades Macro'!$F6 -> 7 | E17: =COUNTIFS('Atividades Micro'!$A$2:$A$554,$B17,'Atividades Micro'!$G$2:$G$554,"Macro",'Atividades Micro'!$J$2:$J$554,E$12) -> 2 | F17: =COUNTIFS('Atividades Micro'!$A$2:$A$554,$B17,'Atividades Micro'!$G$2:$G$554,"Macro",'Atividades Micro'!$J$2:$J$554,"Em andamento")-COUNTIFS('Atividades Micro'!$A$2:$A$554,$B17,'Atividades Micro'!$G$2:$G$554,"Micro",'Atividades Micro'!$E$2:$E$554,"*QA*",'Atividades Micro'!$J$2:$J$554,"Em andamento") -> 2 | G17: =COUNTIFS('Atividades Micro'!$A$2:$A$554,$B17,'Atividades Micro'!$G$2:$G$554,"Micro",'Atividades Micro'!$E$2:$E$554,"*QA*",'Atividades Micro'!$J$2:$J$554,"Em andamento") -> 0 | H17: =COUNTIFS('Atividades Micro'!$A$2:$A$554,$B17,'Atividades Micro'!$G$2:$G$554,"Macro",'Atividades Micro'!$J$2:$J$554,H$12) -> 0 | I17: =COUNTIFS('Atividades Micro'!$A$2:$A$554,$B17,'Atividades Micro'!$G$2:$G$554,"Macro",'Atividades Micro'!$J$2:$J$554,I$12) -> 1 | J17: =COUNTIFS('Atividades Micro'!$A$2:$A$554,$B17,'Atividades Micro'!$G$2:$G$554,"Macro",'Atividades Micro'!$J$2:$J$554,J$12) -> 2 | K17: 0.1025641
A18: ='Atividades Macro'!$B7 -> (Financeiro) Aderência | B18: ='Atividades Macro'!$C7 -> Financeiro | C18: =IF('Atividades Macro'!$D7="","",'Atividades Macro'!$D7) -> 46238 | D18: ='Atividades Macro'!$F7 -> 3 | E18: =COUNTIFS('Atividades Micro'!$B$2:$B$554,$A18,'Atividades Micro'!$G$2:$G$554,"Macro",'Atividades Micro'!$J$2:$J$554,E$12) -> 0 | F18: =COUNTIFS('Atividades Micro'!$B$2:$B$554,$A18,'Atividades Micro'!$G$2:$G$554,"Macro",'Atividades Micro'!$J$2:$J$554,"Em andamento")-COUNTIFS('Atividades Micro'!$B$2:$B$554,$A18,'Atividades Micro'!$G$2:$G$554,"Micro",'Atividades Micro'!$E$2:$E$554,"*QA*",'Atividades Micro'!$J$2:$J$554,"Em andamento") -> 0 | G18: =COUNTIFS('Atividades Micro'!$B$2:$B$554,$A18,'Atividades Micro'!$G$2:$G$554,"Micro",'Atividades Micro'!$E$2:$E$554,"*QA*",'Atividades Micro'!$J$2:$J$554,"Em andamento") -> 0 | H18: =COUNTIFS('Atividades Micro'!$B$2:$B$554,$A18,'Atividades Micro'!$G$2:$G$554,"Macro",'Atividades Micro'!$J$2:$J$554,H$12) -> 0 | I18: =COUNTIFS('Atividades Micro'!$B$2:$B$554,$A18,'Atividades Micro'!$G$2:$G$554,"Macro",'Atividades Micro'!$J$2:$J$554,I$12) -> 1 | J18: =COUNTIFS('Atividades Micro'!$B$2:$B$554,$A18,'Atividades Micro'!$G$2:$G$554,"Macro",'Atividades Micro'!$J$2:$J$554,J$12) -> 2 | K18: 0.71428571
A19: ='Atividades Macro'!$B8 -> (Financeiro) Satélites | B19: ='Atividades Macro'!$C8 -> Financeiro | C19: =IF('Atividades Macro'!$D8="","",'Atividades Macro'!$D8) -> 46374 | D19: ='Atividades Macro'!$F8 -> 4 | E19: =COUNTIFS('Atividades Micro'!$B$2:$B$554,$A19,'Atividades Micro'!$G$2:$G$554,"Macro",'Atividades Micro'!$J$2:$J$554,E$12) -> 2 | F19: =COUNTIFS('Atividades Micro'!$B$2:$B$554,$A19,'Atividades Micro'!$G$2:$G$554,"Macro",'Atividades Micro'!$J$2:$J$554,"Em andamento")-COUNTIFS('Atividades Micro'!$B$2:$B$554,$A19,'Atividades Micro'!$G$2:$G$554,"Micro",'Atividades Micro'!$E$2:$E$554,"*QA*",'Atividades Micro'!$J$2:$J$554,"Em andamento") -> 2 | G19: =COUNTIFS('Atividades Micro'!$B$2:$B$554,$A19,'Atividades Micro'!$G$2:$G$554,"Micro",'Atividades Micro'!$E$2:$E$554,"*QA*",'Atividades Micro'!$J$2:$J$554,"Em andamento") -> 0 | H19: =COUNTIFS('Atividades Micro'!$B$2:$B$554,$A19,'Atividades Micro'!$G$2:$G$554,"Macro",'Atividades Micro'!$J$2:$J$554,H$12) -> 0 | I19: =COUNTIFS('Atividades Micro'!$B$2:$B$554,$A19,'Atividades Micro'!$G$2:$G$554,"Macro",'Atividades Micro'!$J$2:$J$554,I$12) -> 0 | J19: =COUNTIFS('Atividades Micro'!$B$2:$B$554,$A19,'Atividades Micro'!$G$2:$G$554,"Macro",'Atividades Micro'!$J$2:$J$554,J$12) -> 0 | K19: 0.042253521 | M19: * Gedi, Aptus e Nimbi
A20: ='Atividades Macro'!$B9 -> FISCAL | Fusão - Grupo Petz Cobasi | B20: ='Atividades Macro'!$C9 -> Fiscal | C20: =IF('Atividades Macro'!$D9="","",'Atividades Macro'!$D9) | D20: ='Atividades Macro'!$F9 -> 2 | E20: =COUNTIFS('Atividades Micro'!$A$2:$A$554,$B20,'Atividades Micro'!$G$2:$G$554,"Macro",'Atividades Micro'!$J$2:$J$554,E$12) -> 0 | F20: =COUNTIFS('Atividades Micro'!$A$2:$A$554,$B20,'Atividades Micro'!$G$2:$G$554,"Macro",'Atividades Micro'!$J$2:$J$554,"Em andamento")-COUNTIFS('Atividades Micro'!$A$2:$A$554,$B20,'Atividades Micro'!$G$2:$G$554,"Micro",'Atividades Micro'!$E$2:$E$554,"*QA*",'Atividades Micro'!$J$2:$J$554,"Em andamento") -> 1 | G20: =COUNTIFS('Atividades Micro'!$A$2:$A$554,$B20,'Atividades Micro'!$G$2:$G$554,"Micro",'Atividades Micro'!$E$2:$E$554,"*QA*",'Atividades Micro'!$J$2:$J$554,"Em andamento") -> 0 | H20: =COUNTIFS('Atividades Micro'!$A$2:$A$554,$B20,'Atividades Micro'!$G$2:$G$554,"Macro",'Atividades Micro'!$J$2:$J$554,H$12) -> 0 | I20: =COUNTIFS('Atividades Micro'!$A$2:$A$554,$B20,'Atividades Micro'!$G$2:$G$554,"Macro",'Atividades Micro'!$J$2:$J$554,I$12) -> 1 | J20: =COUNTIFS('Atividades Micro'!$A$2:$A$554,$B20,'Atividades Micro'!$G$2:$G$554,"Macro",'Atividades Micro'!$J$2:$J$554,J$12) -> 0 | K20: ='Atividades Macro'!$O$9 -> 0
A21: ='Atividades Macro'!$B11 -> (Fiscal) Satélites | B21: ='Atividades Macro'!$C11 -> Fiscal | C21: =IF('Atividades Macro'!$D11="","",'Atividades Macro'!$D11) -> 46379 | D21: ='Atividades Macro'!$F11 -> 1 | E21: =COUNTIFS('Atividades Micro'!$B$2:$B$554,$A21,'Atividades Micro'!$G$2:$G$554,"Macro",'Atividades Micro'!$J$2:$J$554,E$12) -> 0 | F21: =COUNTIFS('Atividades Micro'!$B$2:$B$554,$A21,'Atividades Micro'!$G$2:$G$554,"Macro",'Atividades Micro'!$J$2:$J$554,"Em andamento")-COUNTIFS('Atividades Micro'!$B$2:$B$554,$A21,'Atividades Micro'!$G$2:$G$554,"Micro",'Atividades Micro'!$E$2:$E$554,"*QA*",'Atividades Micro'!$J$2:$J$554,"Em andamento") -> 1 | G21: =COUNTIFS('Atividades Micro'!$B$2:$B$554,$A21,'Atividades Micro'!$G$2:$G$554,"Micro",'Atividades Micro'!$E$2:$E$554,"*QA*",'Atividades Micro'!$J$2:$J$554,"Em andamento") -> 0 | H21: =COUNTIFS('Atividades Micro'!$B$2:$B$554,$A21,'Atividades Micro'!$G$2:$G$554,"Macro",'Atividades Micro'!$J$2:$J$554,H$12) -> 0 | I21: =COUNTIFS('Atividades Micro'!$B$2:$B$554,$A21,'Atividades Micro'!$G$2:$G$554,"Macro",'Atividades Micro'!$J$2:$J$554,I$12) -> 0 | J21: =COUNTIFS('Atividades Micro'!$B$2:$B$554,$A21,'Atividades Micro'!$G$2:$G$554,"Macro",'Atividades Micro'!$J$2:$J$554,J$12) -> 0 | K21: 0 | M21: * Turin
A22: ='Atividades Macro'!$B10 -> (Fiscal) Aderência | B22: ='Atividades Macro'!$C10 -> Fiscal | C22: =IF('Atividades Macro'!$D10="","",'Atividades Macro'!$D10) | D22: ='Atividades Macro'!$F10 -> 1 | E22: =COUNTIFS('Atividades Micro'!$B$2:$B$554,$A21,'Atividades Micro'!$G$2:$G$554,"Macro",'Atividades Micro'!$J$2:$J$554,E$12) -> 0 | F22: =COUNTIFS('Atividades Micro'!$B$2:$B$554,$A22,'Atividades Micro'!$G$2:$G$554,"Macro",'Atividades Micro'!$J$2:$J$554,"Em andamento")-COUNTIFS('Atividades Micro'!$B$2:$B$554,$A22,'Atividades Micro'!$G$2:$G$554,"Micro",'Atividades Micro'!$E$2:$E$554,"*QA*",'Atividades Micro'!$J$2:$J$554,"Em andamento") -> 0 | G22: =COUNTIFS('Atividades Micro'!$B$2:$B$554,$A22,'Atividades Micro'!$G$2:$G$554,"Micro",'Atividades Micro'!$E$2:$E$554,"*QA*",'Atividades Micro'!$J$2:$J$554,"Em andamento") -> 0 | H22: =COUNTIFS('Atividades Micro'!$B$2:$B$554,$A22,'Atividades Micro'!$G$2:$G$554,"Macro",'Atividades Micro'!$J$2:$J$554,H$12) -> 0 | I22: =COUNTIFS('Atividades Micro'!$B$2:$B$554,$A22,'Atividades Micro'!$G$2:$G$554,"Macro",'Atividades Micro'!$J$2:$J$554,I$12) -> 1 | J22: =COUNTIFS('Atividades Micro'!$B$2:$B$554,$A22,'Atividades Micro'!$G$2:$G$554,"Macro",'Atividades Micro'!$J$2:$J$554,J$12) -> 0 | K22: 0
A23: ='Atividades Macro'!$B12 -> CONTÁBIL | Fusão - Grupo Petz Cobasi | B23: ='Atividades Macro'!$C12 -> Contábil | C23: =IF('Atividades Macro'!$D12="","",'Atividades Macro'!$D12) -> 46374 | D23: ='Atividades Macro'!$F12 -> 18 | E23: =COUNTIFS('Atividades Micro'!$A$2:$A$554,$B23,'Atividades Micro'!$G$2:$G$554,"Macro",'Atividades Micro'!$J$2:$J$554,E$12) -> 0 | F23: =COUNTIFS('Atividades Micro'!$A$2:$A$554,$B23,'Atividades Micro'!$G$2:$G$554,"Macro",'Atividades Micro'!$J$2:$J$554,"Em andamento")-COUNTIFS('Atividades Micro'!$A$2:$A$554,$B23,'Atividades Micro'!$G$2:$G$554,"Micro",'Atividades Micro'!$E$2:$E$554,"*QA*",'Atividades Micro'!$J$2:$J$554,"Em andamento") -> 2 | G23: =COUNTIFS('Atividades Micro'!$A$2:$A$554,$B23,'Atividades Micro'!$G$2:$G$554,"Micro",'Atividades Micro'!$E$2:$E$554,"*QA*",'Atividades Micro'!$J$2:$J$554,"Em andamento") -> 0 | H23: =COUNTIFS('Atividades Micro'!$A$2:$A$554,$B23,'Atividades Micro'!$G$2:$G$554,"Macro",'Atividades Micro'!$J$2:$J$554,H$12) -> 12 | I23: =COUNTIFS('Atividades Micro'!$A$2:$A$554,$B23,'Atividades Micro'!$G$2:$G$554,"Macro",'Atividades Micro'!$J$2:$J$554,I$12) -> 3 | J23: =COUNTIFS('Atividades Micro'!$A$2:$A$554,$B23,'Atividades Micro'!$G$2:$G$554,"Macro",'Atividades Micro'!$J$2:$J$554,J$12) -> 1 | K23: ='Atividades Macro'!$O$12 -> 0.088888889
A24: ='Atividades Macro'!$B13 -> (Contábil) Aderência | B24: ='Atividades Macro'!$C13 -> Contábil | C24: =IF('Atividades Macro'!$D13="","",'Atividades Macro'!$D13) -> 46339 | D24: ='Atividades Macro'!$F13 -> 15 | E24: =COUNTIFS('Atividades Micro'!$B$2:$B$554,$A24,'Atividades Micro'!$G$2:$G$554,"Macro",'Atividades Micro'!$J$2:$J$554,E$12) -> 0 | F24: =COUNTIFS('Atividades Micro'!$B$2:$B$554,$A24,'Atividades Micro'!$G$2:$G$554,"Macro",'Atividades Micro'!$J$2:$J$554,"Em andamento")-COUNTIFS('Atividades Micro'!$B$2:$B$554,$A24,'Atividades Micro'!$G$2:$G$554,"Micro",'Atividades Micro'!$E$2:$E$554,"*QA*",'Atividades Micro'!$J$2:$J$554,"Em andamento") -> 2 | G24: =COUNTIFS('Atividades Micro'!$B$2:$B$554,$A24,'Atividades Micro'!$G$2:$G$554,"Micro",'Atividades Micro'!$E$2:$E$554,"*QA*",'Atividades Micro'!$J$2:$J$554,"Em andamento") -> 0 | H24: =COUNTIFS('Atividades Micro'!$B$2:$B$554,$A24,'Atividades Micro'!$G$2:$G$554,"Macro",'Atividades Micro'!$J$2:$J$554,H$12) -> 12 | I24: =COUNTIFS('Atividades Micro'!$B$2:$B$554,$A24,'Atividades Micro'!$G$2:$G$554,"Macro",'Atividades Micro'!$J$2:$J$554,I$12) -> 0 | J24: =COUNTIFS('Atividades Micro'!$B$2:$B$554,$A24,'Atividades Micro'!$G$2:$G$554,"Macro",'Atividades Micro'!$J$2:$J$554,J$12) -> 1 | K24: 0.044444444
A25: ='Atividades Macro'!$B14 -> (Contábil) Satélites | B25: ='Atividades Macro'!$C14 -> Contábil | C25: =IF('Atividades Macro'!$D14="","",'Atividades Macro'!$D14) | D25: ='Atividades Macro'!$F14 -> 3 | E25: =COUNTIFS('Atividades Micro'!$B$2:$B$554,$A25,'Atividades Micro'!$G$2:$G$554,"Macro",'Atividades Micro'!$J$2:$J$554,E$12) -> 0 | F25: =COUNTIFS('Atividades Micro'!$B$2:$B$554,$A25,'Atividades Micro'!$G$2:$G$554,"Macro",'Atividades Micro'!$J$2:$J$554,"Em andamento")-COUNTIFS('Atividades Micro'!$B$2:$B$554,$A25,'Atividades Micro'!$G$2:$G$554,"Micro",'Atividades Micro'!$E$2:$E$554,"*QA*",'Atividades Micro'!$J$2:$J$554,"Em andamento") -> 0 | G25: =COUNTIFS('Atividades Micro'!$B$2:$B$554,$A25,'Atividades Micro'!$G$2:$G$554,"Micro",'Atividades Micro'!$E$2:$E$554,"*QA*",'Atividades Micro'!$J$2:$J$554,"Em andamento") -> 0 | H25: =COUNTIFS('Atividades Micro'!$B$2:$B$554,$A25,'Atividades Micro'!$G$2:$G$554,"Macro",'Atividades Micro'!$J$2:$J$554,H$12) -> 0 | I25: =COUNTIFS('Atividades Micro'!$B$2:$B$554,$A25,'Atividades Micro'!$G$2:$G$554,"Macro",'Atividades Micro'!$J$2:$J$554,I$12) -> 3 | J25: =COUNTIFS('Atividades Micro'!$B$2:$B$554,$A25,'Atividades Micro'!$G$2:$G$554,"Macro",'Atividades Micro'!$J$2:$J$554,J$12) -> 0 | K25: 0
A26: ='Atividades Macro'!$B15 -> SUPPLY| Fusão - Petz Cobasi | B26: ='Atividades Macro'!$C15 -> Supply | C26: =IF('Atividades Macro'!$D15="","",'Atividades Macro'!$D15) -> 46290 | D26: ='Atividades Macro'!$F15 -> 6 | E26: =COUNTIFS('Atividades Micro'!$A$2:$A$554,$B26,'Atividades Micro'!$G$2:$G$554,"Macro",'Atividades Micro'!$J$2:$J$554,E$12) -> 0 | F26: =COUNTIFS('Atividades Micro'!$A$2:$A$554,$B26,'Atividades Micro'!$G$2:$G$554,"Macro",'Atividades Micro'!$J$2:$J$554,"Em andamento")-COUNTIFS('Atividades Micro'!$A$2:$A$554,$B26,'Atividades Micro'!$G$2:$G$554,"Micro",'Atividades Micro'!$E$2:$E$554,"*QA*",'Atividades Micro'!$J$2:$J$554,"Em andamento") -> 4 | G26: =COUNTIFS('Atividades Micro'!$A$2:$A$554,$B26,'Atividades Micro'!$G$2:$G$554,"Micro",'Atividades Micro'!$E$2:$E$554,"*QA*",'Atividades Micro'!$J$2:$J$554,"Em andamento") -> 0 | H26: =COUNTIFS('Atividades Micro'!$A$2:$A$554,$B26,'Atividades Micro'!$G$2:$G$554,"Macro",'Atividades Micro'!$J$2:$J$554,H$12) -> 0 | I26: =COUNTIFS('Atividades Micro'!$A$2:$A$554,$B26,'Atividades Micro'!$G$2:$G$554,"Macro",'Atividades Micro'!$J$2:$J$554,I$12) -> 0 | J26: =COUNTIFS('Atividades Micro'!$A$2:$A$554,$B26,'Atividades Micro'!$G$2:$G$554,"Macro",'Atividades Micro'!$J$2:$J$554,J$12) -> 2 | K26: 0.26666667
A27: ='Atividades Macro'!$B16 -> (Supply) Aderência | B27: ='Atividades Macro'!$C16 -> Supply | C27: =IF('Atividades Macro'!$D16="","",'Atividades Macro'!$D16) -> 46276 | D27: ='Atividades Macro'!$F16 -> 2 | E27: =COUNTIFS('Atividades Micro'!$B$2:$B$554,$A27,'Atividades Micro'!$G$2:$G$554,"Macro",'Atividades Micro'!$J$2:$J$554,E$12) -> 0 | F27: =COUNTIFS('Atividades Micro'!$B$2:$B$554,$A27,'Atividades Micro'!$G$2:$G$554,"Macro",'Atividades Micro'!$J$2:$J$554,"Em andamento")-COUNTIFS('Atividades Micro'!$B$2:$B$554,$A27,'Atividades Micro'!$G$2:$G$554,"Micro",'Atividades Micro'!$E$2:$E$554,"*QA*",'Atividades Micro'!$J$2:$J$554,"Em andamento") -> 0 | G27: =COUNTIFS('Atividades Micro'!$B$2:$B$554,$A27,'Atividades Micro'!$G$2:$G$554,"Micro",'Atividades Micro'!$E$2:$E$554,"*QA*",'Atividades Micro'!$J$2:$J$554,"Em andamento") -> 0 | H27: =COUNTIFS('Atividades Micro'!$B$2:$B$554,$A27,'Atividades Micro'!$G$2:$G$554,"Macro",'Atividades Micro'!$J$2:$J$554,H$12) -> 0 | I27: =COUNTIFS('Atividades Micro'!$B$2:$B$554,$A27,'Atividades Micro'!$G$2:$G$554,"Macro",'Atividades Micro'!$J$2:$J$554,I$12) -> 0 | J27: =COUNTIFS('Atividades Micro'!$B$2:$B$554,$A27,'Atividades Micro'!$G$2:$G$554,"Macro",'Atividades Micro'!$J$2:$J$554,J$12) -> 2 | K27: 0.66666667
A28: ='Atividades Macro'!$B17 -> (Supply) Satélites | B28: ='Atividades Macro'!$C17 -> Supply | C28: =IF('Atividades Macro'!$D17="","",'Atividades Macro'!$D17) -> 46374 | D28: ='Atividades Macro'!$F17 -> 4 | E28: =COUNTIFS('Atividades Micro'!$B$2:$B$554,$A28,'Atividades Micro'!$G$2:$G$554,"Macro",'Atividades Micro'!$J$2:$J$554,E$12) -> 0 | F28: =COUNTIFS('Atividades Micro'!$B$2:$B$554,$A28,'Atividades Micro'!$G$2:$G$554,"Macro",'Atividades Micro'!$J$2:$J$554,"Em andamento")-COUNTIFS('Atividades Micro'!$B$2:$B$554,$A28,'Atividades Micro'!$G$2:$G$554,"Micro",'Atividades Micro'!$E$2:$E$554,"*QA*",'Atividades Micro'!$J$2:$J$554,"Em andamento") -> 4 | G28: =COUNTIFS('Atividades Micro'!$B$2:$B$554,$A28,'Atividades Micro'!$G$2:$G$554,"Micro",'Atividades Micro'!$E$2:$E$554,"*QA*",'Atividades Micro'!$J$2:$J$554,"Em andamento") -> 0 | H28: =COUNTIFS('Atividades Micro'!$B$2:$B$554,$A28,'Atividades Micro'!$G$2:$G$554,"Macro",'Atividades Micro'!$J$2:$J$554,H$12) -> 0 | I28: =COUNTIFS('Atividades Micro'!$B$2:$B$554,$A28,'Atividades Micro'!$G$2:$G$554,"Macro",'Atividades Micro'!$J$2:$J$554,I$12) -> 0 | J28: =COUNTIFS('Atividades Micro'!$B$2:$B$554,$A28,'Atividades Micro'!$G$2:$G$554,"Macro",'Atividades Micro'!$J$2:$J$554,J$12) -> 0 | K28: 0 | M28: * Portal do Fornecedor - TOTVS
A29: ='Atividades Macro'!$B18 -> CD | Fusão - Grupo Petz Cobasi | B29: ='Atividades Macro'!$C18 -> CD | C29: =IF('Atividades Macro'!$D18="","",'Atividades Macro'!$D18) -> 46374 | D29: ='Atividades Macro'!$F18 -> 18 | E29: =COUNTIFS('Atividades Micro'!$A$2:$A$554,$B29,'Atividades Micro'!$G$2:$G$554,"Macro",'Atividades Micro'!$J$2:$J$554,E$12) -> 3 | F29: =COUNTIFS('Atividades Micro'!$A$2:$A$554,$B29,'Atividades Micro'!$G$2:$G$554,"Macro",'Atividades Micro'!$J$2:$J$554,"Em andamento")-COUNTIFS('Atividades Micro'!$A$2:$A$554,$B29,'Atividades Micro'!$G$2:$G$554,"Micro",'Atividades Micro'!$E$2:$E$554,"*QA*",'Atividades Micro'!$J$2:$J$554,"Em andamento") -> -1 | G29: =COUNTIFS('Atividades Micro'!$A$2:$A$554,$B29,'Atividades Micro'!$G$2:$G$554,"Micro",'Atividades Micro'!$E$2:$E$554,"*QA*",'Atividades Micro'!$J$2:$J$554,"Em andamento") -> 1 | H29: =COUNTIFS('Atividades Micro'!$A$2:$A$554,$B29,'Atividades Micro'!$G$2:$G$554,"Macro",'Atividades Micro'!$J$2:$J$554,H$12) -> 0 | I29: =COUNTIFS('Atividades Micro'!$A$2:$A$554,$B29,'Atividades Micro'!$G$2:$G$554,"Macro",'Atividades Micro'!$J$2:$J$554,I$12) -> 4 | J29: =COUNTIFS('Atividades Micro'!$A$2:$A$554,$B29,'Atividades Micro'!$G$2:$G$554,"Macro",'Atividades Micro'!$J$2:$J$554,J$12) -> 11 | K29: 0.14285714
A30: ='Atividades Macro'!$B19 -> (CD) Aderência | B30: ='Atividades Macro'!$C19 -> CD | C30: =IF('Atividades Macro'!$D19="","",'Atividades Macro'!$D19) -> 46385 | D30: ='Atividades Macro'!$F19 -> 14 | E30: =COUNTIFS('Atividades Micro'!$B$2:$B$554,$A30,'Atividades Micro'!$G$2:$G$554,"Macro",'Atividades Micro'!$J$2:$J$554,E$12) -> 2 | F30: =COUNTIFS('Atividades Micro'!$B$2:$B$554,$A30,'Atividades Micro'!$G$2:$G$554,"Macro",'Atividades Micro'!$J$2:$J$554,"Em andamento")-COUNTIFS('Atividades Micro'!$B$2:$B$554,$A30,'Atividades Micro'!$G$2:$G$554,"Micro",'Atividades Micro'!$E$2:$E$554,"*QA*",'Atividades Micro'!$J$2:$J$554,"Em andamento") -> -1 | G30: =COUNTIFS('Atividades Micro'!$B$2:$B$554,$A30,'Atividades Micro'!$G$2:$G$554,"Micro",'Atividades Micro'!$E$2:$E$554,"*QA*",'Atividades Micro'!$J$2:$J$554,"Em andamento") -> 1 | H30: =COUNTIFS('Atividades Micro'!$B$2:$B$554,$A30,'Atividades Micro'!$G$2:$G$554,"Macro",'Atividades Micro'!$J$2:$J$554,H$12) -> 0 | I30: =COUNTIFS('Atividades Micro'!$B$2:$B$554,$A30,'Atividades Micro'!$G$2:$G$554,"Macro",'Atividades Micro'!$J$2:$J$554,I$12) -> 1 | J30: =COUNTIFS('Atividades Micro'!$B$2:$B$554,$A30,'Atividades Micro'!$G$2:$G$554,"Macro",'Atividades Micro'!$J$2:$J$554,J$12) -> 11 | K30: 0.15384615
A31: ='Atividades Macro'!$B20 -> (CD) Satélites | B31: ='Atividades Macro'!$C20 -> CD | C31: =IF('Atividades Macro'!$D20="","",'Atividades Macro'!$D20) -> 46279 | D31: ='Atividades Macro'!$F20 -> 4 | E31: =COUNTIFS('Atividades Micro'!$B$2:$B$554,$A31,'Atividades Micro'!$G$2:$G$554,"Macro",'Atividades Micro'!$J$2:$J$554,E$12) -> 1 | F31: =COUNTIFS('Atividades Micro'!$B$2:$B$554,$A31,'Atividades Micro'!$G$2:$G$554,"Macro",'Atividades Micro'!$J$2:$J$554,"Em andamento")-COUNTIFS('Atividades Micro'!$B$2:$B$554,$A31,'Atividades Micro'!$G$2:$G$554,"Micro",'Atividades Micro'!$E$2:$E$554,"*QA*",'Atividades Micro'!$J$2:$J$554,"Em andamento") -> 0 | G31: =COUNTIFS('Atividades Micro'!$B$2:$B$554,$A31,'Atividades Micro'!$G$2:$G$554,"Micro",'Atividades Micro'!$E$2:$E$554,"*QA*",'Atividades Micro'!$J$2:$J$554,"Em andamento") -> 0 | H31: =COUNTIFS('Atividades Micro'!$B$2:$B$554,$A31,'Atividades Micro'!$G$2:$G$554,"Macro",'Atividades Micro'!$J$2:$J$554,H$12) -> 0 | I31: =COUNTIFS('Atividades Micro'!$B$2:$B$554,$A31,'Atividades Micro'!$G$2:$G$554,"Macro",'Atividades Micro'!$J$2:$J$554,I$12) -> 3 | J31: =COUNTIFS('Atividades Micro'!$B$2:$B$554,$A31,'Atividades Micro'!$G$2:$G$554,"Macro",'Atividades Micro'!$J$2:$J$554,J$12) -> 0 | K31: 0.1 | M31: *(VPO) Open Tech, TMS Multi (CTE)
A32: ='Atividades Macro'!$B21 -> COMERCIAL | Fusão - Petz Cobasi | B32: ='Atividades Macro'!$C21 -> Comercial | C32: =IF('Atividades Macro'!$D21="","",'Atividades Macro'!$D21) -> 46304 | D32: ='Atividades Macro'!$F21 -> 4 | E32: =COUNTIFS('Atividades Micro'!$A$2:$A$554,$B32,'Atividades Micro'!$G$2:$G$554,"Macro",'Atividades Micro'!$J$2:$J$554,E$12) -> 2 | F32: =COUNTIFS('Atividades Micro'!$A$2:$A$554,$B32,'Atividades Micro'!$G$2:$G$554,"Macro",'Atividades Micro'!$J$2:$J$554,"Em andamento")-COUNTIFS('Atividades Micro'!$A$2:$A$554,$B32,'Atividades Micro'!$G$2:$G$554,"Micro",'Atividades Micro'!$E$2:$E$554,"*QA*",'Atividades Micro'!$J$2:$J$554,"Em andamento") -> 1 | G32: =COUNTIFS('Atividades Micro'!$A$2:$A$554,$B32,'Atividades Micro'!$G$2:$G$554,"Micro",'Atividades Micro'!$E$2:$E$554,"*QA*",'Atividades Micro'!$J$2:$J$554,"Em andamento") -> 0 | H32: =COUNTIFS('Atividades Micro'!$A$2:$A$554,$B32,'Atividades Micro'!$G$2:$G$554,"Macro",'Atividades Micro'!$J$2:$J$554,H$12) -> 0 | I32: =COUNTIFS('Atividades Micro'!$A$2:$A$554,$B32,'Atividades Micro'!$G$2:$G$554,"Macro",'Atividades Micro'!$J$2:$J$554,I$12) -> 0 | J32: =COUNTIFS('Atividades Micro'!$A$2:$A$554,$B32,'Atividades Micro'!$G$2:$G$554,"Macro",'Atividades Micro'!$J$2:$J$554,J$12) -> 1 | K32: 0.090909091
A33: ='Atividades Macro'!$B22 -> (Comercial) Aderência | B33: ='Atividades Macro'!$C22 -> Comercial | C33: =IF('Atividades Macro'!$D22="","",'Atividades Macro'!$D22) -> 46279 | D33: ='Atividades Macro'!$F22 -> 2 | E33: =COUNTIFS('Atividades Micro'!$B$2:$B$554,$A33,'Atividades Micro'!$G$2:$G$554,"Macro",'Atividades Micro'!$J$2:$J$554,E$12) -> 1 | F33: =COUNTIFS('Atividades Micro'!$B$2:$B$554,$A33,'Atividades Micro'!$G$2:$G$554,"Macro",'Atividades Micro'!$J$2:$J$554,"Em andamento")-COUNTIFS('Atividades Micro'!$B$2:$B$554,$A33,'Atividades Micro'!$G$2:$G$554,"Micro",'Atividades Micro'!$E$2:$E$554,"*QA*",'Atividades Micro'!$J$2:$J$554,"Em andamento") -> 0 | G33: =COUNTIFS('Atividades Micro'!$B$2:$B$554,$A33,'Atividades Micro'!$G$2:$G$554,"Micro",'Atividades Micro'!$E$2:$E$554,"*QA*",'Atividades Micro'!$J$2:$J$554,"Em andamento") -> 0 | H33: =COUNTIFS('Atividades Micro'!$B$2:$B$554,$A33,'Atividades Micro'!$G$2:$G$554,"Macro",'Atividades Micro'!$J$2:$J$554,H$12) -> 0 | I33: =COUNTIFS('Atividades Micro'!$B$2:$B$554,$A33,'Atividades Micro'!$G$2:$G$554,"Macro",'Atividades Micro'!$J$2:$J$554,I$12) -> 0 | J33: =COUNTIFS('Atividades Micro'!$B$2:$B$554,$A33,'Atividades Micro'!$G$2:$G$554,"Macro",'Atividades Micro'!$J$2:$J$554,J$12) -> 1 | K33: 0.16666667
A34: ='Atividades Macro'!$B23 -> (Comercial) Satélites | B34: ='Atividades Macro'!$C23 -> Comercial | C34: =IF('Atividades Macro'!$D23="","",'Atividades Macro'!$D23) -> 46301 | D34: ='Atividades Macro'!$F23 -> 2 | E34: =COUNTIFS('Atividades Micro'!$B$2:$B$554,$A34,'Atividades Micro'!$G$2:$G$554,"Macro",'Atividades Micro'!$J$2:$J$554,E$12) -> 1 | F34: =COUNTIFS('Atividades Micro'!$B$2:$B$554,$A34,'Atividades Micro'!$G$2:$G$554,"Macro",'Atividades Micro'!$J$2:$J$554,"Em andamento")-COUNTIFS('Atividades Micro'!$B$2:$B$554,$A34,'Atividades Micro'!$G$2:$G$554,"Micro",'Atividades Micro'!$E$2:$E$554,"*QA*",'Atividades Micro'!$J$2:$J$554,"Em andamento") -> 1 | G34: =COUNTIFS('Atividades Micro'!$B$2:$B$554,$A34,'Atividades Micro'!$G$2:$G$554,"Micro",'Atividades Micro'!$E$2:$E$554,"*QA*",'Atividades Micro'!$J$2:$J$554,"Em andamento") -> 0 | H34: =COUNTIFS('Atividades Micro'!$B$2:$B$554,$A34,'Atividades Micro'!$G$2:$G$554,"Macro",'Atividades Micro'!$J$2:$J$554,H$12) -> 0 | I34: =COUNTIFS('Atividades Micro'!$B$2:$B$554,$A34,'Atividades Micro'!$G$2:$G$554,"Macro",'Atividades Micro'!$J$2:$J$554,I$12) -> 0 | J34: =COUNTIFS('Atividades Micro'!$B$2:$B$554,$A34,'Atividades Micro'!$G$2:$G$554,"Macro",'Atividades Micro'!$J$2:$J$554,J$12) -> 0 | K34: 0 | M34: *SOLUTIS
A35: ='Atividades Macro'!$B24 -> TOTVS / RM | Fusão Petz Cobasi | B35: ='Atividades Macro'!$C24 -> TOTVS RM | C35: =IF('Atividades Macro'!$D24="","",'Atividades Macro'!$D24) -> 46321 | D35: ='Atividades Macro'!$F24 -> 1 | E35: =COUNTIFS('Atividades Micro'!$A$2:$A$554,$B35,'Atividades Micro'!$G$2:$G$554,"Macro",'Atividades Micro'!$J$2:$J$554,E$12) -> 0 | F35: =COUNTIFS('Atividades Micro'!$A$2:$A$554,$B35,'Atividades Micro'!$G$2:$G$554,"Macro",'Atividades Micro'!$J$2:$J$554,"Em andamento")-COUNTIFS('Atividades Micro'!$A$2:$A$554,$B35,'Atividades Micro'!$G$2:$G$554,"Micro",'Atividades Micro'!$E$2:$E$554,"*QA*",'Atividades Micro'!$J$2:$J$554,"Em andamento") -> 1 | G35: =COUNTIFS('Atividades Micro'!$A$2:$A$554,$B35,'Atividades Micro'!$G$2:$G$554,"Micro",'Atividades Micro'!$E$2:$E$554,"*QA*",'Atividades Micro'!$J$2:$J$554,"Em andamento") -> 0 | H35: =COUNTIFS('Atividades Micro'!$A$2:$A$554,$B35,'Atividades Micro'!$G$2:$G$554,"Macro",'Atividades Micro'!$J$2:$J$554,H$12) -> 0 | I35: =COUNTIFS('Atividades Micro'!$A$2:$A$554,$B35,'Atividades Micro'!$G$2:$G$554,"Macro",'Atividades Micro'!$J$2:$J$554,I$12) -> 0 | J35: =COUNTIFS('Atividades Micro'!$A$2:$A$554,$B35,'Atividades Micro'!$G$2:$G$554,"Macro",'Atividades Micro'!$J$2:$J$554,J$12) -> 0 | K35: 0.1
A36: ='Atividades Macro'!$B25 -> (TOTVS RM) Aderência | B36: ='Atividades Macro'!$C25 -> TOTVS RM | C36: =IF('Atividades Macro'!$D25="","",'Atividades Macro'!$D25) -> 46342 | D36: ='Atividades Macro'!$F25 -> 1 | E36: =COUNTIFS('Atividades Micro'!$B$2:$B$554,$A36,'Atividades Micro'!$G$2:$G$554,"Macro",'Atividades Micro'!$J$2:$J$554,E$12) -> 0 | F36: =COUNTIFS('Atividades Micro'!$B$2:$B$554,$A36,'Atividades Micro'!$G$2:$G$554,"Macro",'Atividades Micro'!$J$2:$J$554,"Em andamento")-COUNTIFS('Atividades Micro'!$B$2:$B$554,$A36,'Atividades Micro'!$G$2:$G$554,"Micro",'Atividades Micro'!$E$2:$E$554,"*QA*",'Atividades Micro'!$J$2:$J$554,"Em andamento") -> 1 | G36: =COUNTIFS('Atividades Micro'!$B$2:$B$554,$A36,'Atividades Micro'!$G$2:$G$554,"Micro",'Atividades Micro'!$E$2:$E$554,"*QA*",'Atividades Micro'!$J$2:$J$554,"Em andamento") -> 0 | H36: =COUNTIFS('Atividades Micro'!$B$2:$B$554,$A36,'Atividades Micro'!$G$2:$G$554,"Macro",'Atividades Micro'!$J$2:$J$554,H$12) -> 0 | I36: =COUNTIFS('Atividades Micro'!$B$2:$B$554,$A36,'Atividades Micro'!$G$2:$G$554,"Macro",'Atividades Micro'!$J$2:$J$554,I$12) -> 0 | J36: =COUNTIFS('Atividades Micro'!$B$2:$B$554,$A36,'Atividades Micro'!$G$2:$G$554,"Macro",'Atividades Micro'!$J$2:$J$554,J$12) -> 0 | K36: 0.1
A37: ='Atividades Macro'!$B26 -> ZANTHUS PDV | Fusão Petz Cobasi | B37: ='Atividades Macro'!$C26 -> Zanthus | C37: =IF('Atividades Macro'!$D26="","",'Atividades Macro'!$D26) -> 46337 | D37: ='Atividades Macro'!$F26 -> 1 | E37: =COUNTIFS('Atividades Micro'!$A$2:$A$554,$B37,'Atividades Micro'!$G$2:$G$554,"Macro",'Atividades Micro'!$J$2:$J$554,E$12) -> 0 | F37: =COUNTIFS('Atividades Micro'!$A$2:$A$554,$B37,'Atividades Micro'!$G$2:$G$554,"Macro",'Atividades Micro'!$J$2:$J$554,"Em andamento")-COUNTIFS('Atividades Micro'!$A$2:$A$554,$B37,'Atividades Micro'!$G$2:$G$554,"Micro",'Atividades Micro'!$E$2:$E$554,"*QA*",'Atividades Micro'!$J$2:$J$554,"Em andamento") -> 1 | G37: =COUNTIFS('Atividades Micro'!$A$2:$A$554,$B37,'Atividades Micro'!$G$2:$G$554,"Micro",'Atividades Micro'!$E$2:$E$554,"*QA*",'Atividades Micro'!$J$2:$J$554,"Em andamento") -> 0 | H37: =COUNTIFS('Atividades Micro'!$A$2:$A$554,$B37,'Atividades Micro'!$G$2:$G$554,"Macro",'Atividades Micro'!$J$2:$J$554,H$12) -> 0 | I37: =COUNTIFS('Atividades Micro'!$A$2:$A$554,$B37,'Atividades Micro'!$G$2:$G$554,"Macro",'Atividades Micro'!$J$2:$J$554,I$12) -> 0 | J37: =COUNTIFS('Atividades Micro'!$A$2:$A$554,$B37,'Atividades Micro'!$G$2:$G$554,"Macro",'Atividades Micro'!$J$2:$J$554,J$12) -> 0 | K37: 0.26666667
A38: ='Atividades Macro'!$B27 -> (Zanthus) Aderência | B38: ='Atividades Macro'!$C27 -> Zanthus | C38: =IF('Atividades Macro'!$D27="","",'Atividades Macro'!$D27) -> 46338 | D38: ='Atividades Macro'!$F27 -> 1 | E38: =COUNTIFS('Atividades Micro'!$B$2:$B$554,$A38,'Atividades Micro'!$G$2:$G$554,"Macro",'Atividades Micro'!$J$2:$J$554,E$12) -> 0 | F38: =COUNTIFS('Atividades Micro'!$B$2:$B$554,$A38,'Atividades Micro'!$G$2:$G$554,"Macro",'Atividades Micro'!$J$2:$J$554,"Em andamento")-COUNTIFS('Atividades Micro'!$B$2:$B$554,$A38,'Atividades Micro'!$G$2:$G$554,"Micro",'Atividades Micro'!$E$2:$E$554,"*QA*",'Atividades Micro'!$J$2:$J$554,"Em andamento") -> 1 | G38: =COUNTIFS('Atividades Micro'!$B$2:$B$554,$A38,'Atividades Micro'!$G$2:$G$554,"Micro",'Atividades Micro'!$E$2:$E$554,"*QA*",'Atividades Micro'!$J$2:$J$554,"Em andamento") -> 0 | H38: =COUNTIFS('Atividades Micro'!$B$2:$B$554,$A38,'Atividades Micro'!$G$2:$G$554,"Macro",'Atividades Micro'!$J$2:$J$554,H$12) -> 0 | I38: =COUNTIFS('Atividades Micro'!$B$2:$B$554,$A38,'Atividades Micro'!$G$2:$G$554,"Macro",'Atividades Micro'!$J$2:$J$554,I$12) -> 0 | J38: =COUNTIFS('Atividades Micro'!$B$2:$B$554,$A38,'Atividades Micro'!$G$2:$G$554,"Macro",'Atividades Micro'!$J$2:$J$554,J$12) -> 0 | K38: 0.26666667
A39: ='Atividades Macro'!$B28 -> OPERAÇÕES | Fusão - Petz Cobasi | B39: ='Atividades Macro'!$C28 -> Operações | C39: =IF('Atividades Macro'!$D28="","",'Atividades Macro'!$D28) -> 46288 | D39: ='Atividades Macro'!$F28 -> 2 | E39: =COUNTIFS('Atividades Micro'!$A$2:$A$554,$B39,'Atividades Micro'!$G$2:$G$554,"Macro",'Atividades Micro'!$J$2:$J$554,E$12) -> 0 | F39: =COUNTIFS('Atividades Micro'!$A$2:$A$554,$B39,'Atividades Micro'!$G$2:$G$554,"Macro",'Atividades Micro'!$J$2:$J$554,"Em andamento")-COUNTIFS('Atividades Micro'!$A$2:$A$554,$B39,'Atividades Micro'!$G$2:$G$554,"Micro",'Atividades Micro'!$E$2:$E$554,"*QA*",'Atividades Micro'!$J$2:$J$554,"Em andamento") -> 1 | G39: =COUNTIFS('Atividades Micro'!$A$2:$A$554,$B39,'Atividades Micro'!$G$2:$G$554,"Micro",'Atividades Micro'!$E$2:$E$554,"*QA*",'Atividades Micro'!$J$2:$J$554,"Em andamento") -> 0 | H39: =COUNTIFS('Atividades Micro'!$A$2:$A$554,$B39,'Atividades Micro'!$G$2:$G$554,"Macro",'Atividades Micro'!$J$2:$J$554,H$12) -> 0 | I39: =COUNTIFS('Atividades Micro'!$A$2:$A$554,$B39,'Atividades Micro'!$G$2:$G$554,"Macro",'Atividades Micro'!$J$2:$J$554,I$12) -> 1 | J39: =COUNTIFS('Atividades Micro'!$A$2:$A$554,$B39,'Atividades Micro'!$G$2:$G$554,"Macro",'Atividades Micro'!$J$2:$J$554,J$12) -> 0 | K39: 0
A40: ='Atividades Macro'!$B29 -> (Operações) Satélites | B40: ='Atividades Macro'!$C29 -> Operações | C40: =IF('Atividades Macro'!$D29="","",'Atividades Macro'!$D29) -> 46352 | D40: ='Atividades Macro'!$F29 -> 2 | E40: =COUNTIFS('Atividades Micro'!$B$2:$B$554,$A40,'Atividades Micro'!$G$2:$G$554,"Macro",'Atividades Micro'!$J$2:$J$554,E$12) -> 0 | F40: =COUNTIFS('Atividades Micro'!$B$2:$B$554,$A40,'Atividades Micro'!$G$2:$G$554,"Macro",'Atividades Micro'!$J$2:$J$554,"Em andamento")-COUNTIFS('Atividades Micro'!$B$2:$B$554,$A40,'Atividades Micro'!$G$2:$G$554,"Micro",'Atividades Micro'!$E$2:$E$554,"*QA*",'Atividades Micro'!$J$2:$J$554,"Em andamento") -> 1 | G40: =COUNTIFS('Atividades Micro'!$B$2:$B$554,$A40,'Atividades Micro'!$G$2:$G$554,"Micro",'Atividades Micro'!$E$2:$E$554,"*QA*",'Atividades Micro'!$J$2:$J$554,"Em andamento") -> 0 | H40: =COUNTIFS('Atividades Micro'!$B$2:$B$554,$A40,'Atividades Micro'!$G$2:$G$554,"Macro",'Atividades Micro'!$J$2:$J$554,H$12) -> 0 | I40: =COUNTIFS('Atividades Micro'!$B$2:$B$554,$A40,'Atividades Micro'!$G$2:$G$554,"Macro",'Atividades Micro'!$J$2:$J$554,I$12) -> 1 | J40: =COUNTIFS('Atividades Micro'!$B$2:$B$554,$A40,'Atividades Micro'!$G$2:$G$554,"Macro",'Atividades Micro'!$J$2:$J$554,J$12) -> 0 | K40: 0 | M40: * Tecsus
A55: A aba apresenta somente o andamento das atividades Macro. Canceladas permanecem na quantidade total e na coluna própria, mas não compõem o denominador da % concluída. Percentuais em vermelho indicam Data Planejada alcançada ou vencida com entrega pendente.

Sheet Painel Executivo Micro
A1: ="STATUS FUSÃO | PAINEL EXECUTIVO – ATIVIDADES - Frentes acompanhadas:"&COUNTA('Resumo por Frente'!$A$5:$A$17) -> STATUS FUSÃO | PAINEL EXECUTIVO – ATIVIDADES - Frentes acompanhadas:13
A3: Leitura do andamento das atividades Micro | Canceladas fora do total ativo e do cálculo percentual
A5: Andamento das atividades Micro | K5: ="Total: "&COUNTIFS('Atividades Micro'!$G$2:$G$554,"Micro",'Atividades Micro'!$J$2:$J$554,"<>Cancelado") -> Total: 215
A6: Não iniciado | C6: Em andamento | E6: Testes QA | G6: Bloqueado | I6: Cancelado | K6: Finalizado
A7: =COUNTIFS('Atividades Micro'!$G$2:$G$554,"Micro",'Atividades Micro'!$J$2:$J$554,"Não iniciado") -> 48 | C7: =COUNTIFS('Atividades Micro'!$G$2:$G$554,"Micro",'Atividades Micro'!$J$2:$J$554,"Em andamento",'Atividades Micro'!$E$2:$E$554,"<>*QA*") -> 24 | E7: =COUNTIFS('Atividades Micro'!$G$2:$G$554,"Micro",'Atividades Micro'!$E$2:$E$554,"*QA*",'Atividades Micro'!$J$2:$J$554,"Em andamento") -> 1 | G7: =COUNTIFS('Atividades Micro'!$G$2:$G$554,"Micro",'Atividades Micro'!$J$2:$J$554,"Bloqueado") -> 25 | I7: =COUNTIFS('Atividades Micro'!$G$2:$G$554,"Micro",'Atividades Micro'!$J$2:$J$554,"Cancelado") -> 31 | K7: =COUNTIFS('Atividades Micro'!$G$2:$G$554,"Micro",'Atividades Micro'!$J$2:$J$554,"Finalizado") -> 117
A8: =IF(COUNTIFS('Atividades Micro'!$G$2:$G$554,"Micro",'Atividades Micro'!$J$2:$J$554,"<>Cancelado")<=0,0,COUNTIFS('Atividades Micro'!$G$2:$G$554,"Micro",'Atividades Micro'!$J$2:$J$554,"Não iniciado")/COUNTIFS('Atividades Micro'!$G$2:$G$554,"Micro",'Atividades Micro'!$J$2:$J$554,"<>Cancelado")) -> 0.22325581 | C8: =IF(COUNTIFS('Atividades Micro'!$G$2:$G$554,"Micro",'Atividades Micro'!$J$2:$J$554,"<>Cancelado")<=0,0,C7/COUNTIFS('Atividades Micro'!$G$2:$G$554,"Micro",'Atividades Micro'!$J$2:$J$554,"<>Cancelado")) -> 0.11162791 | E8: =IF(COUNTIFS('Atividades Micro'!$G$2:$G$554,"Micro",'Atividades Micro'!$J$2:$J$554,"<>Cancelado")<=0,0,E7/COUNTIFS('Atividades Micro'!$G$2:$G$554,"Micro",'Atividades Micro'!$J$2:$J$554,"<>Cancelado")) -> 0.0046511628 | G8: =IF(COUNTIFS('Atividades Micro'!$G$2:$G$554,"Micro",'Atividades Micro'!$J$2:$J$554,"<>Cancelado")<=0,0,COUNTIFS('Atividades Micro'!$G$2:$G$554,"Micro",'Atividades Micro'!$J$2:$J$554,"Bloqueado")/COUNTIFS('Atividades Micro'!$G$2:$G$554,"Micro",'Atividades Micro'!$J$2:$J$554,"<>Cancelado")) -> 0.11627907 | I8: Fora do cálculo | K8: =IF(COUNTIFS('Atividades Micro'!$G$2:$G$554,"Micro",'Atividades Micro'!$J$2:$J$554,"<>Cancelado")<=0,0,COUNTIFS('Atividades Micro'!$G$2:$G$554,"Micro",'Atividades Micro'!$J$2:$J$554,"Finalizado")/COUNTIFS('Atividades Micro'!$G$2:$G$554,"Micro",'Atividades Micro'!$J$2:$J$554,"<>Cancelado")) -> 0.54418605
A11: Evolução das atividades Micro — Aderência e Satélites
A12: Linha de atividade micro | B12: Frente | C12: Data Planejada | D12: Atividades micro | E12: Não iniciado | F12: Em andamento | G12: Testes QA | H12: Bloqueado | I12: Cancelado | J12: Finalizado | K12: % concluído
A13: ='Atividades Macro'!$B7 -> (Financeiro) Aderência | B13: ='Atividades Macro'!$C7 -> Financeiro | C13: =IF('Atividades Macro'!$D7="","",'Atividades Macro'!$D7) -> 46238 | D13: ='Atividades Macro'!$G7 -> 6 | E13: =COUNTIFS('Atividades Micro'!$B$2:$B$554,$A13,'Atividades Micro'!$G$2:$G$554,"Micro",'Atividades Micro'!$J$2:$J$554,E$12) -> 1 | F13: =COUNTIFS('Atividades Micro'!$B$2:$B$554,$A13,'Atividades Micro'!$G$2:$G$554,"Micro",'Atividades Micro'!$J$2:$J$554,"Em andamento",'Atividades Micro'!$E$2:$E$554,"<>*QA*") -> 0 | G13: =COUNTIFS('Atividades Micro'!$B$2:$B$554,$A13,'Atividades Micro'!$G$2:$G$554,"Micro",'Atividades Micro'!$E$2:$E$554,"*QA*",'Atividades Micro'!$J$2:$J$554,"Em andamento") -> 0 | H13: =COUNTIFS('Atividades Micro'!$B$2:$B$554,$A13,'Atividades Micro'!$G$2:$G$554,"Micro",'Atividades Micro'!$J$2:$J$554,H$12) -> 0 | I13: =COUNTIFS('Atividades Micro'!$B$2:$B$554,$A13,'Atividades Micro'!$G$2:$G$554,"Micro",'Atividades Micro'!$J$2:$J$554,I$12) -> 2 | J13: =COUNTIFS('Atividades Micro'!$B$2:$B$554,$A13,'Atividades Micro'!$G$2:$G$554,"Micro",'Atividades Micro'!$J$2:$J$554,J$12) -> 5 | K13: =IF(D13<=0,0,J13/D13) -> 0.83333333
A14: ='Atividades Macro'!$B8 -> (Financeiro) Satélites | B14: ='Atividades Macro'!$C8 -> Financeiro | C14: =IF('Atividades Macro'!$D8="","",'Atividades Macro'!$D8) -> 46374 | D14: ='Atividades Macro'!$G8 -> 69 | E14: =COUNTIFS('Atividades Micro'!$B$2:$B$554,$A14,'Atividades Micro'!$G$2:$G$554,"Micro",'Atividades Micro'!$J$2:$J$554,E$12) -> 20 | F14: =COUNTIFS('Atividades Micro'!$B$2:$B$554,$A14,'Atividades Micro'!$G$2:$G$554,"Micro",'Atividades Micro'!$J$2:$J$554,"Em andamento",'Atividades Micro'!$E$2:$E$554,"<>*QA*") -> 5 | G14: =COUNTIFS('Atividades Micro'!$B$2:$B$554,$A14,'Atividades Micro'!$G$2:$G$554,"Micro",'Atividades Micro'!$E$2:$E$554,"*QA*",'Atividades Micro'!$J$2:$J$554,"Em andamento") -> 0 | H14: =COUNTIFS('Atividades Micro'!$B$2:$B$554,$A14,'Atividades Micro'!$G$2:$G$554,"Micro",'Atividades Micro'!$J$2:$J$554,H$12) -> 0 | I14: =COUNTIFS('Atividades Micro'!$B$2:$B$554,$A14,'Atividades Micro'!$G$2:$G$554,"Micro",'Atividades Micro'!$J$2:$J$554,I$12) -> 12 | J14: =COUNTIFS('Atividades Micro'!$B$2:$B$554,$A14,'Atividades Micro'!$G$2:$G$554,"Micro",'Atividades Micro'!$J$2:$J$554,J$12) -> 44 | K14: =IF(D14<=0,0,J14/D14) -> 0.63768116
A15: ='Atividades Macro'!$B11 -> (Fiscal) Satélites | B15: ='Atividades Macro'!$C11 -> Fiscal | C15: =IF('Atividades Macro'!$D11="","",'Atividades Macro'!$D11) -> 46379 | D15: ='Atividades Macro'!$G11 -> 3 | E15: =COUNTIFS('Atividades Micro'!$B$2:$B$554,$A15,'Atividades Micro'!$G$2:$G$554,"Micro",'Atividades Micro'!$J$2:$J$554,E$12) -> 1 | F15: =COUNTIFS('Atividades Micro'!$B$2:$B$554,$A15,'Atividades Micro'!$G$2:$G$554,"Micro",'Atividades Micro'!$J$2:$J$554,"Em andamento",'Atividades Micro'!$E$2:$E$554,"<>*QA*") -> 2 | G15: =COUNTIFS('Atividades Micro'!$B$2:$B$554,$A15,'Atividades Micro'!$G$2:$G$554,"Micro",'Atividades Micro'!$E$2:$E$554,"*QA*",'Atividades Micro'!$J$2:$J$554,"Em andamento") -> 0 | H15: =COUNTIFS('Atividades Micro'!$B$2:$B$554,$A15,'Atividades Micro'!$G$2:$G$554,"Micro",'Atividades Micro'!$J$2:$J$554,H$12) -> 0 | I15: =COUNTIFS('Atividades Micro'!$B$2:$B$554,$A15,'Atividades Micro'!$G$2:$G$554,"Micro",'Atividades Micro'!$J$2:$J$554,I$12) -> 4 | J15: =COUNTIFS('Atividades Micro'!$B$2:$B$554,$A15,'Atividades Micro'!$G$2:$G$554,"Micro",'Atividades Micro'!$J$2:$J$554,J$12) -> 0 | K15: =IF(D15<=0,0,J15/D15) -> 0
A16: ='Atividades Macro'!$B10 -> (Fiscal) Aderência | B16: ='Atividades Macro'!$C10 -> Fiscal | C16: =IF('Atividades Macro'!$D10="","",'Atividades Macro'!$D10) | D16: ='Atividades Macro'!$G10 -> 0 | E16: =COUNTIFS('Atividades Micro'!$B$2:$B$554,$A16,'Atividades Micro'!$G$2:$G$554,"Micro",'Atividades Micro'!$J$2:$J$554,E$12) -> 0 | F16: =COUNTIFS('Atividades Micro'!$B$2:$B$554,$A16,'Atividades Micro'!$G$2:$G$554,"Micro",'Atividades Micro'!$J$2:$J$554,"Em andamento",'Atividades Micro'!$E$2:$E$554,"<>*QA*") -> 0 | G16: =COUNTIFS('Atividades Micro'!$B$2:$B$554,$A16,'Atividades Micro'!$G$2:$G$554,"Micro",'Atividades Micro'!$E$2:$E$554,"*QA*",'Atividades Micro'!$J$2:$J$554,"Em andamento") -> 0 | H16: =COUNTIFS('Atividades Micro'!$B$2:$B$554,$A16,'Atividades Micro'!$G$2:$G$554,"Micro",'Atividades Micro'!$J$2:$J$554,H$12) -> 0 | I16: =COUNTIFS('Atividades Micro'!$B$2:$B$554,$A16,'Atividades Micro'!$G$2:$G$554,"Micro",'Atividades Micro'!$J$2:$J$554,I$12) -> 1 | J16: =COUNTIFS('Atividades Micro'!$B$2:$B$554,$A16,'Atividades Micro'!$G$2:$G$554,"Micro",'Atividades Micro'!$J$2:$J$554,J$12) -> 0 | K16: =IF(D16<=0,0,J16/D16) -> 0
A17: ='Atividades Macro'!$B13 -> (Contábil) Aderência | B17: ='Atividades Macro'!$C13 -> Contábil | C17: =IF('Atividades Macro'!$D13="","",'Atividades Macro'!$D13) -> 46339 | D17: ='Atividades Macro'!$G13 -> 30 | E17: =COUNTIFS('Atividades Micro'!$B$2:$B$554,$A17,'Atividades Micro'!$G$2:$G$554,"Micro",'Atividades Micro'!$J$2:$J$554,E$12) -> 1 | F17: =COUNTIFS('Atividades Micro'!$B$2:$B$554,$A17,'Atividades Micro'!$G$2:$G$554,"Micro",'Atividades Micro'!$J$2:$J$554,"Em andamento",'Atividades Micro'!$E$2:$E$554,"<>*QA*") -> 1 | G17: =COUNTIFS('Atividades Micro'!$B$2:$B$554,$A17,'Atividades Micro'!$G$2:$G$554,"Micro",'Atividades Micro'!$E$2:$E$554,"*QA*",'Atividades Micro'!$J$2:$J$554,"Em andamento") -> 0 | H17: =COUNTIFS('Atividades Micro'!$B$2:$B$554,$A17,'Atividades Micro'!$G$2:$G$554,"Micro",'Atividades Micro'!$J$2:$J$554,H$12) -> 25 | I17: =COUNTIFS('Atividades Micro'!$B$2:$B$554,$A17,'Atividades Micro'!$G$2:$G$554,"Micro",'Atividades Micro'!$J$2:$J$554,I$12) -> 0 | J17: =COUNTIFS('Atividades Micro'!$B$2:$B$554,$A17,'Atividades Micro'!$G$2:$G$554,"Micro",'Atividades Micro'!$J$2:$J$554,J$12) -> 3 | K17: =IF(D17<=0,0,J17/D17) -> 0.1
A18: ='Atividades Macro'!$B14 -> (Contábil) Satélites | B18: ='Atividades Macro'!$C14 -> Contábil | C18: =IF('Atividades Macro'!$D14="","",'Atividades Macro'!$D14) | D18: ='Atividades Macro'!$G14 -> 0 | E18: =COUNTIFS('Atividades Micro'!$B$2:$B$554,$A18,'Atividades Micro'!$G$2:$G$554,"Micro",'Atividades Micro'!$J$2:$J$554,E$12) -> 0 | F18: =COUNTIFS('Atividades Micro'!$B$2:$B$554,$A18,'Atividades Micro'!$G$2:$G$554,"Micro",'Atividades Micro'!$J$2:$J$554,"Em andamento",'Atividades Micro'!$E$2:$E$554,"<>*QA*") -> 0 | G18: =COUNTIFS('Atividades Micro'!$B$2:$B$554,$A18,'Atividades Micro'!$G$2:$G$554,"Micro",'Atividades Micro'!$E$2:$E$554,"*QA*",'Atividades Micro'!$J$2:$J$554,"Em andamento") -> 0 | H18: =COUNTIFS('Atividades Micro'!$B$2:$B$554,$A18,'Atividades Micro'!$G$2:$G$554,"Micro",'Atividades Micro'!$J$2:$J$554,H$12) -> 0 | I18: =COUNTIFS('Atividades Micro'!$B$2:$B$554,$A18,'Atividades Micro'!$G$2:$G$554,"Micro",'Atividades Micro'!$J$2:$J$554,I$12) -> 0 | J18: =COUNTIFS('Atividades Micro'!$B$2:$B$554,$A18,'Atividades Micro'!$G$2:$G$554,"Micro",'Atividades Micro'!$J$2:$J$554,J$12) -> 0 | K18: =IF(D18<=0,0,J18/D18) -> 0
A19: ='Atividades Macro'!$B16 -> (Supply) Aderência | B19: ='Atividades Macro'!$C16 -> Supply | C19: =IF('Atividades Macro'!$D16="","",'Atividades Macro'!$D16) -> 46276 | D19: ='Atividades Macro'!$G16 -> 4 | E19: =COUNTIFS('Atividades Micro'!$B$2:$B$554,$A19,'Atividades Micro'!$G$2:$G$554,"Micro",'Atividades Micro'!$J$2:$J$554,E$12) -> 0 | F19: =COUNTIFS('Atividades Micro'!$B$2:$B$554,$A19,'Atividades Micro'!$G$2:$G$554,"Micro",'Atividades Micro'!$J$2:$J$554,"Em andamento",'Atividades Micro'!$E$2:$E$554,"<>*QA*") -> 0 | G19: =COUNTIFS('Atividades Micro'!$B$2:$B$554,$A19,'Atividades Micro'!$G$2:$G$554,"Micro",'Atividades Micro'!$E$2:$E$554,"*QA*",'Atividades Micro'!$J$2:$J$554,"Em andamento") -> 0 | H19: =COUNTIFS('Atividades Micro'!$B$2:$B$554,$A19,'Atividades Micro'!$G$2:$G$554,"Micro",'Atividades Micro'!$J$2:$J$554,H$12) -> 0 | I19: =COUNTIFS('Atividades Micro'!$B$2:$B$554,$A19,'Atividades Micro'!$G$2:$G$554,"Micro",'Atividades Micro'!$J$2:$J$554,I$12) -> 0 | J19: =COUNTIFS('Atividades Micro'!$B$2:$B$554,$A19,'Atividades Micro'!$G$2:$G$554,"Micro",'Atividades Micro'!$J$2:$J$554,J$12) -> 4 | K19: =IF(D19<=0,0,J19/D19) -> 1
A20: ='Atividades Macro'!$B17 -> (Supply) Satélites | B20: ='Atividades Macro'!$C17 -> Supply | C20: =IF('Atividades Macro'!$D17="","",'Atividades Macro'!$D17) -> 46374 | D20: ='Atividades Macro'!$G17 -> 14 | E20: =COUNTIFS('Atividades Micro'!$B$2:$B$554,$A20,'Atividades Micro'!$G$2:$G$554,"Micro",'Atividades Micro'!$J$2:$J$554,E$12) -> 6 | F20: =COUNTIFS('Atividades Micro'!$B$2:$B$554,$A20,'Atividades Micro'!$G$2:$G$554,"Micro",'Atividades Micro'!$J$2:$J$554,"Em andamento",'Atividades Micro'!$E$2:$E$554,"<>*QA*") -> 3 | G20: =COUNTIFS('Atividades Micro'!$B$2:$B$554,$A20,'Atividades Micro'!$G$2:$G$554,"Micro",'Atividades Micro'!$E$2:$E$554,"*QA*",'Atividades Micro'!$J$2:$J$554,"Em andamento") -> 0 | H20: =COUNTIFS('Atividades Micro'!$B$2:$B$554,$A20,'Atividades Micro'!$G$2:$G$554,"Micro",'Atividades Micro'!$J$2:$J$554,H$12) -> 0 | I20: =COUNTIFS('Atividades Micro'!$B$2:$B$554,$A20,'Atividades Micro'!$G$2:$G$554,"Micro",'Atividades Micro'!$J$2:$J$554,I$12) -> 3 | J20: =COUNTIFS('Atividades Micro'!$B$2:$B$554,$A20,'Atividades Micro'!$G$2:$G$554,"Micro",'Atividades Micro'!$J$2:$J$554,J$12) -> 5 | K20: =IF(D20<=0,0,J20/D20) -> 0.35714286
A21: ='Atividades Macro'!$B19 -> (CD) Aderência | B21: ='Atividades Macro'!$C19 -> CD | C21: =IF('Atividades Macro'!$D19="","",'Atividades Macro'!$D19) -> 46385 | D21: ='Atividades Macro'!$G19 -> 41 | E21: =COUNTIFS('Atividades Micro'!$B$2:$B$554,$A21,'Atividades Micro'!$G$2:$G$554,"Micro",'Atividades Micro'!$J$2:$J$554,E$12) -> 9 | F21: =COUNTIFS('Atividades Micro'!$B$2:$B$554,$A21,'Atividades Micro'!$G$2:$G$554,"Micro",'Atividades Micro'!$J$2:$J$554,"Em andamento",'Atividades Micro'!$E$2:$E$554,"<>*QA*") -> 5 | G21: =COUNTIFS('Atividades Micro'!$B$2:$B$554,$A21,'Atividades Micro'!$G$2:$G$554,"Micro",'Atividades Micro'!$E$2:$E$554,"*QA*",'Atividades Micro'!$J$2:$J$554,"Em andamento") -> 1 | H21: =COUNTIFS('Atividades Micro'!$B$2:$B$554,$A21,'Atividades Micro'!$G$2:$G$554,"Micro",'Atividades Micro'!$J$2:$J$554,H$12) -> 0 | I21: =COUNTIFS('Atividades Micro'!$B$2:$B$554,$A21,'Atividades Micro'!$G$2:$G$554,"Micro",'Atividades Micro'!$J$2:$J$554,I$12) -> 0 | J21: =COUNTIFS('Atividades Micro'!$B$2:$B$554,$A21,'Atividades Micro'!$G$2:$G$554,"Micro",'Atividades Micro'!$J$2:$J$554,J$12) -> 26 | K21: =IF(D21<=0,0,J21/D21) -> 0.63414634
A22: ='Atividades Macro'!$B20 -> (CD) Satélites | B22: ='Atividades Macro'!$C20 -> CD | C22: =IF('Atividades Macro'!$D20="","",'Atividades Macro'!$D20) -> 46279 | D22: ='Atividades Macro'!$G20 -> 5 | E22: =COUNTIFS('Atividades Micro'!$B$2:$B$554,$A22,'Atividades Micro'!$G$2:$G$554,"Micro",'Atividades Micro'!$J$2:$J$554,E$12) -> 2 | F22: =COUNTIFS('Atividades Micro'!$B$2:$B$554,$A22,'Atividades Micro'!$G$2:$G$554,"Micro",'Atividades Micro'!$J$2:$J$554,"Em andamento",'Atividades Micro'!$E$2:$E$554,"<>*QA*") -> 1 | G22: =COUNTIFS('Atividades Micro'!$B$2:$B$554,$A22,'Atividades Micro'!$G$2:$G$554,"Micro",'Atividades Micro'!$E$2:$E$554,"*QA*",'Atividades Micro'!$J$2:$J$554,"Em andamento") -> 0 | H22: =COUNTIFS('Atividades Micro'!$B$2:$B$554,$A22,'Atividades Micro'!$G$2:$G$554,"Micro",'Atividades Micro'!$J$2:$J$554,H$12) -> 0 | I22: =COUNTIFS('Atividades Micro'!$B$2:$B$554,$A22,'Atividades Micro'!$G$2:$G$554,"Micro",'Atividades Micro'!$J$2:$J$554,I$12) -> 3 | J22: =COUNTIFS('Atividades Micro'!$B$2:$B$554,$A22,'Atividades Micro'!$G$2:$G$554,"Micro",'Atividades Micro'!$J$2:$J$554,J$12) -> 2 | K22: =IF(D22<=0,0,J22/D22) -> 0.4
A23: ='Atividades Macro'!$B22 -> (Comercial) Aderência | B23: ='Atividades Macro'!$C22 -> Comercial | C23: =IF('Atividades Macro'!$D22="","",'Atividades Macro'!$D22) -> 46279 | D23: ='Atividades Macro'!$G22 -> 5 | E23: =COUNTIFS('Atividades Micro'!$B$2:$B$554,$A23,'Atividades Micro'!$G$2:$G$554,"Micro",'Atividades Micro'!$J$2:$J$554,E$12) -> 2 | F23: =COUNTIFS('Atividades Micro'!$B$2:$B$554,$A23,'Atividades Micro'!$G$2:$G$554,"Micro",'Atividades Micro'!$J$2:$J$554,"Em andamento",'Atividades Micro'!$E$2:$E$554,"<>*QA*") -> 0 | G23: =COUNTIFS('Atividades Micro'!$B$2:$B$554,$A23,'Atividades Micro'!$G$2:$G$554,"Micro",'Atividades Micro'!$E$2:$E$554,"*QA*",'Atividades Micro'!$J$2:$J$554,"Em andamento") -> 0 | H23: =COUNTIFS('Atividades Micro'!$B$2:$B$554,$A23,'Atividades Micro'!$G$2:$G$554,"Micro",'Atividades Micro'!$J$2:$J$554,H$12) -> 0 | I23: =COUNTIFS('Atividades Micro'!$B$2:$B$554,$A23,'Atividades Micro'!$G$2:$G$554,"Micro",'Atividades Micro'!$J$2:$J$554,I$12) -> 0 | J23: =COUNTIFS('Atividades Micro'!$B$2:$B$554,$A23,'Atividades Micro'!$G$2:$G$554,"Micro",'Atividades Micro'!$J$2:$J$554,J$12) -> 3 | K23: =IF(D23<=0,0,J23/D23) -> 0.6
A24: ='Atividades Macro'!$B23 -> (Comercial) Satélites | B24: ='Atividades Macro'!$C23 -> Comercial | C24: =IF('Atividades Macro'!$D23="","",'Atividades Macro'!$D23) -> 46301 | D24: ='Atividades Macro'!$G23 -> 9 | E24: =COUNTIFS('Atividades Micro'!$B$2:$B$554,$A24,'Atividades Micro'!$G$2:$G$554,"Micro",'Atividades Micro'!$J$2:$J$554,E$12) -> 3 | F24: =COUNTIFS('Atividades Micro'!$B$2:$B$554,$A24,'Atividades Micro'!$G$2:$G$554,"Micro",'Atividades Micro'!$J$2:$J$554,"Em andamento",'Atividades Micro'!$E$2:$E$554,"<>*QA*") -> 2 | G24: =COUNTIFS('Atividades Micro'!$B$2:$B$554,$A24,'Atividades Micro'!$G$2:$G$554,"Micro",'Atividades Micro'!$E$2:$E$554,"*QA*",'Atividades Micro'!$J$2:$J$554,"Em andamento") -> 0 | H24: =COUNTIFS('Atividades Micro'!$B$2:$B$554,$A24,'Atividades Micro'!$G$2:$G$554,"Micro",'Atividades Micro'!$J$2:$J$554,H$12) -> 0 | I24: =COUNTIFS('Atividades Micro'!$B$2:$B$554,$A24,'Atividades Micro'!$G$2:$G$554,"Micro",'Atividades Micro'!$J$2:$J$554,I$12) -> 4 | J24: =COUNTIFS('Atividades Micro'!$B$2:$B$554,$A24,'Atividades Micro'!$G$2:$G$554,"Micro",'Atividades Micro'!$J$2:$J$554,J$12) -> 4 | K24: =IF(D24<=0,0,J24/D24) -> 0.44444444
A25: ='Atividades Macro'!$B29 -> (Operações) Satélites | B25: ='Atividades Macro'!$C29 -> Operações | C25: =IF('Atividades Macro'!$D29="","",'Atividades Macro'!$D29) -> 46352 | D25: ='Atividades Macro'!$G29 -> 2 | E25: =COUNTIFS('Atividades Micro'!$B$2:$B$554,$A25,'Atividades Micro'!$G$2:$G$554,"Micro",'Atividades Micro'!$J$2:$J$554,E$12) -> 1 | F25: =COUNTIFS('Atividades Micro'!$B$2:$B$554,$A25,'Atividades Micro'!$G$2:$G$554,"Micro",'Atividades Micro'!$J$2:$J$554,"Em andamento",'Atividades Micro'!$E$2:$E$554,"<>*QA*") -> 1 | G25: =COUNTIFS('Atividades Micro'!$B$2:$B$554,$A25,'Atividades Micro'!$G$2:$G$554,"Micro",'Atividades Micro'!$E$2:$E$554,"*QA*",'Atividades Micro'!$J$2:$J$554,"Em andamento") -> 0 | H25: =COUNTIFS('Atividades Micro'!$B$2:$B$554,$A25,'Atividades Micro'!$G$2:$G$554,"Micro",'Atividades Micro'!$J$2:$J$554,H$12) -> 0 | I25: =COUNTIFS('Atividades Micro'!$B$2:$B$554,$A25,'Atividades Micro'!$G$2:$G$554,"Micro",'Atividades Micro'!$J$2:$J$554,I$12) -> 1 | J25: =COUNTIFS('Atividades Micro'!$B$2:$B$554,$A25,'Atividades Micro'!$G$2:$G$554,"Micro",'Atividades Micro'!$J$2:$J$554,J$12) -> 0 | K25: =IF(D25<=0,0,J25/D25) -> 0
A26: (Zanthus) Aderência | B26: Zanthus | C26: =IF('Atividades Macro'!$D27="","",'Atividades Macro'!$D27) -> 46338 | D26: ='Atividades Macro'!$G27 -> 14 | E26: =COUNTIFS('Atividades Micro'!$B$2:$B$554,$A26,'Atividades Micro'!$G$2:$G$554,"Micro",'Atividades Micro'!$J$2:$J$554,E$12) -> 0 | F26: =COUNTIFS('Atividades Micro'!$B$2:$B$554,$A26,'Atividades Micro'!$G$2:$G$554,"Micro",'Atividades Micro'!$J$2:$J$554,"Em andamento",'Atividades Micro'!$E$2:$E$554,"<>*QA*") -> 1 | G26: =COUNTIFS('Atividades Micro'!$B$2:$B$554,$A26,'Atividades Micro'!$G$2:$G$554,"Micro",'Atividades Micro'!$E$2:$E$554,"*QA*",'Atividades Micro'!$J$2:$J$554,"Em andamento") -> 0 | H26: =COUNTIFS('Atividades Micro'!$B$2:$B$554,$A26,'Atividades Micro'!$G$2:$G$554,"Micro",'Atividades Micro'!$J$2:$J$554,H$12) -> 0 | I26: =COUNTIFS('Atividades Micro'!$B$2:$B$554,$A26,'Atividades Micro'!$G$2:$G$554,"Micro",'Atividades Micro'!$J$2:$J$554,I$12) -> 0 | J26: =COUNTIFS('Atividades Micro'!$B$2:$B$554,$A26,'Atividades Micro'!$G$2:$G$554,"Micro",'Atividades Micro'!$J$2:$J$554,J$12) -> 13 | K26: =IF(D26<=0,0,J26/D26) -> 0.92857143
A27: (TOTVS RM) Aderência | B27: TOTVS RM | C27: =IF('Atividades Macro'!$D25="","",'Atividades Macro'!$D25) -> 46342 | D27: ='Atividades Macro'!$G25 -> 10 | E27: =COUNTIFS('Atividades Micro'!$B$2:$B$554,$A27,'Atividades Micro'!$G$2:$G$554,"Micro",'Atividades Micro'!$J$2:$J$554,E$12) -> 2 | F27: =COUNTIFS('Atividades Micro'!$B$2:$B$554,$A27,'Atividades Micro'!$G$2:$G$554,"Micro",'Atividades Micro'!$J$2:$J$554,"Em andamento",'Atividades Micro'!$E$2:$E$554,"<>*QA*") -> 0 | G27: =COUNTIFS('Atividades Micro'!$B$2:$B$554,$A27,'Atividades Micro'!$G$2:$G$554,"Micro",'Atividades Micro'!$E$2:$E$554,"*QA*",'Atividades Micro'!$J$2:$J$554,"Em andamento") -> 0 | H27: =COUNTIFS('Atividades Micro'!$B$2:$B$554,$A27,'Atividades Micro'!$G$2:$G$554,"Micro",'Atividades Micro'!$J$2:$J$554,H$12) -> 0 | I27: =COUNTIFS('Atividades Micro'!$B$2:$B$554,$A27,'Atividades Micro'!$G$2:$G$554,"Micro",'Atividades Micro'!$J$2:$J$554,I$12) -> 1 | J27: =COUNTIFS('Atividades Micro'!$B$2:$B$554,$A27,'Atividades Micro'!$G$2:$G$554,"Micro",'Atividades Micro'!$J$2:$J$554,J$12) -> 8 | K27: =IF(D27<=0,0,J27/D27) -> 0.8
A42: A aba apresenta somente atividades Micro vinculadas às linhas de Aderência e Satélites, sem as linhas principais Macro. Canceladas ficam visíveis, mas não compõem o total ativo nem o denominador da % concluída. Percentuais em vermelho indicam Data Planejada alcançada ou vencida com entrega pendente.

Sheet Resumo por Frente
A1: ATIVIDADES MACRO POR FRENTE
A2: Quantidade Macro inclui atividades canceladas; canceladas permanecem visíveis em coluna própria e ficam fora somente do percentual concluído.
A4: Frente | B4: Atividades macro | C4: Atividades micro | D4: Não iniciado | E4: Em andamento | F4: Testes QA | G4: Bloqueado | H4: Cancelado | I4: Finalizado | J4: % concluído | K4: Data Planejada | L4: Data fim real
